# 错误处理 5 种策略
## 1. 传播错误
``` go
// findLinks对http.Get的调用失败，findLinks会直接将这个HTTP错误返回给调用者
resp, err := http.Get(url)
if err != nil{
	return nill, err
}

// 当对html.Parse的调用失败时，findLinks不会直接返回html.Parse的错误，
// 因为缺少两条重要信息：1、错误发生在解析器；2、url已经被解析。
// 这些信息有助于错误的处理，findLinks会构造新的错误信息返回给调用者
doc, err := html.Parse(resp.Body)
resp.Body.Close()
if err != nil {
	return nil, fmt.Errorf("parsing %s as HTML: %v", url, err)
}
```

## 2. 重试操作
> [!info] 
> 如果错误的发生是偶然性的，或由不可预知的问题导致的。一个明智的选择是重新尝试失败的操作。在重试时，我们需要限制重试的时间间隔或重试的次数，防止无限制的重试。 
``` go
// WaitForServer attempts to contact the server of a URL.
// It tries for one minute using exponential back‐off.
// It reports an error if all attempts fail.
func WaitForServer(url string) error {
	const timeout = 1 * time.Minute
	deadline := time.Now().Add(timeout)
	for tries := 0; time.Now().Before(deadline); tries++ {
		_, err := http.Head(url)
		if err == nil {
			return nil // success
		}
		log.Printf("server not responding (%s);retrying…", err)
		time.Sleep(time.Second << uint(tries)) // exponential back‐off
	}
	return fmt.Errorf("server %s failed to respond after %s", url, timeout)
}
```

## 3. 输出错误信息并结束程序
> [!info] 
> 输出错误信息并结束程序的策略通常使用 `log.Fatal` 或 `os.Exit` 来实现。这种策略适用于程序的主函数（`main` 函数），因为它表示程序无法继续正常运行，必须立即终止。然而，对于库函数，这种策略是不合适的，库函数应该仅向上传播错误，而不是直接终止程序。 
> - **在 `main` 中**：如果遇到无法恢复的错误，可以使用 `log.Fatal` 或 `os.Exit` 输出错误信息并结束程序。
> - **在库函数中**：应该仅向上传播错误，除非遇到程序内部的不一致性（即 bug），才可以在库函数中使用 `panic` 终止程序。
``` go
package main

import (
    "fmt"
    "os"
)

func main() {
    err := someOperation()
    if err != nil {
        fmt.Fprintf(os.Stderr, "Error: %v\n", err)
        os.Exit(1)
    }
    // 程序继续执行
}

func someOperation() error {
    return fmt.Errorf("something went wrong")
}
```
`log.Fatal` 会输出错误信息并调用 `os.Exit(1)`，表示程序非正常退出
``` go
package main

import (
    "log"
)

func main() {
    err := someOperation()
    if err != nil {
        log.Fatalf("Fatal error: %v", err)
    }
    // 程序继续执行
}

func someOperation() error {
    return fmt.Errorf("something went wrong")
}
```
库函数应该返回错误，让调用者决定如何处理。
``` go
package mylib

import (
    "fmt"
)

func DoSomething() error {
    if someCondition {
        return fmt.Errorf("something went wrong")
    }
    return nil
}
```
如果库函数检测到程序内部存在不一致性（即遇到了 bug），可以使用 `panic` 来终止程序。这种情况下，程序的状态已经无法恢复，继续执行可能会导致更严重的问题。
``` go
package mylib

import (
    "fmt"
)

func DoSomething() error {
    if someCondition {
        panic("internal inconsistency: something went terribly wrong")
    }
    return nil
}
```

## 4. 只需要输出错误信息就足够了，不需要中断程序的运行
> [!info] 
> 有时，我们只需要输出错误信息就足够了，不需要中断程序的运行。我们可以通过log包提供函数

通过log包提供函数
``` go
if err := Ping(); err != nil {
	log.Printf("ping failed: %v; networking disabled", err)
}
```
通过标准错误流输出错误信息
``` go
if err := Ping(); err != nil {
	fmt.Fprintf(os.Stderr,"ping failed: %v; networking disabled\n", err)
}
```

## 5. 直接忽略掉错误
``` go
dir, err := ioutil.TempDir("", "scratch")
if err != nil {
	return fmt.Errorf("failed to create temp dir: %v",err)
}
// ...use temp dir…
os.RemoveAll(dir) // ignore errors; $TMPDIR is cleaned periodically
```

# 文件结尾错误（EOF）
> [!info] 
> 在 Go 语言中，**文件结尾错误（EOF）** 是一个特殊的错误，通常表示文件或数据流的末尾已经到达，无法再读取更多数据。EOF 错误在处理文件、网络连接、标准输入等场景中非常常见。
> `EOF` 是 `io.EOF` 的简称，它是 Go 标准库 `io` 包中定义的一个错误常量
> `var EOF = errors.New("EOF")`
> 
> - **EOF 错误** 是 `io.EOF`，表示数据流已经结束，是读取操作的正常结果。
> - **处理 EOF 错误**：在读取操作中，检查是否返回了 `io.EOF`，如果是，则正常结束读取操作。
> - **区分 EOF 和其他错误**：需要明确区分 `io.EOF` 和其他 I/O 错误，避免将预期错误视为异常。
> - **适用场景**：EOF 错误常见于文件读取、网络连接、标准输入等场景。

``` go
package main

import (
    "fmt"
    "io"
    "os"
)

func main() {
    buf := make([]byte, 1024)
    for {
        n, err := os.Stdin.Read(buf)
        if err != nil {
            if err == io.EOF {
                fmt.Println("Reached end of input")
                break
            }
            fmt.Println("Error reading input:", err)
            return
        }
        fmt.Printf("Read %d bytes: %s\n", n, buf[:n])
    }
}
```



